Workbook
Name Slicer_Store_Name: #N/A
Name Slicer_Lead_Type: #N/A
Name Slicer_Lead_Status: #N/A

Sheet Conversion rates
A3: Count of Lead ID | B3: Lead Status | C3: Cancellation Status
B4: Delivered | D4: Delivered Total | E4: Cancelled | F4: Cancelled Total | G4: Grand Total
A5: Store Name | B5: No | C5: Yes | E5: Yes
A6: Bangalore MBC | B6: 0.72623574 | C6: 0.079847909 | D6: 0.80608365 | E6: 0.19391635 | F6: 0.19391635 | G6: 1
A7: Chennai MBC | B7: 0.72169811 | C7: 0.094339623 | D7: 0.81603774 | E7: 0.18396226 | F7: 0.18396226 | G7: 1
A8: Delhi MBC | B8: 0.70722433 | C8: 0.098859316 | D8: 0.80608365 | E8: 0.19391635 | F8: 0.19391635 | G8: 1
A9: Mumbai MBC | B9: 0.75954198 | C9: 0.061068702 | D9: 0.82061069 | E9: 0.17938931 | F9: 0.17938931 | G9: 1
A10: Grand Total | B10: 0.729 | C10: 0.083 | D10: 0.812 | E10: 0.188 | F10: 0.188 | G10: 1

Sheet Average TAT
A3: Store Name | B3: Avg of Pre-booking TAT (days) | C3: Avg of Booking TAT (days) | D3: Avg of Delivery TAT (days)
A4: Bangalore MBC | B4: 2.513308 | C4: 2.4448669 | D4: 3.6387833
A5: Chennai MBC | B5: 2.5471698 | C5: 2.6132075 | D5: 3.5801887
A6: Delhi MBC | B6: 2.4410646 | C6: 2.4334601 | D6: 3.4524715
A7: Mumbai MBC | B7: 2.4427481 | C7: 2.5 | D7: 3.7977099
A8: Grand Total | B8: 2.483 | C8: 2.492 | D8: 3.619

Sheet Lead Breakdown
A2: Breakdown of Hot/Warm/Cold leads
A3: Count of Lead ID | B3: Lead Type
A4: Store Name | B4: Cold | C4: Hot | D4: Warm | E4: Grand Total
A5: Bangalore MBC | B5: 0.19391635 | C5: 0.30418251 | D5: 0.50190114 | E5: 1
A6: Chennai MBC | B6: 0.18396226 | C6: 0.33018868 | D6: 0.48584906 | E6: 1
A7: Delhi MBC | B7: 0.19391635 | C7: 0.2661597 | D7: 0.53992395 | E7: 1
A8: Mumbai MBC | B8: 0.17938931 | C8: 0.31679389 | D8: 0.50381679 | E8: 1
A9: Grand Total | B9: 0.188 | C9: 0.303 | D9: 0.509 | E9: 1
A12: Lead Type | B12: Count of Leads
A13: Hot | B13: =COUNTIF('Main data'!C:C,"Hot") -> 303
A14: Warm | B14: =COUNTIF('Main data'!C:C,"Warm") -> 509
A15: Cold | B15: =COUNTIF('Main data'!C:C,"Cold") -> 188

Sheet Sheet3
A3: Lead Type | B3: Count of Lead ID
A4: Cold | B4: 188
A5: Hot | B5: 303
A6: Warm | B6: 509
A7: Grand Total | B7: 1000

Sheet Main data
A1: Lead ID | B1: Store Name | C1: Lead Type | D1: Lead Date | E1: Pre-Booking Date | F1: Booking Date | G1: Delivery Date | H1: Lead Status | I1: Pre-booking TAT (days) | J1: Booking TAT (days) | K1: Delivery TAT (days) | L1: Cancellation Status | M1: Cancellation Reason | N1: Service Follow-up Date | O1: TAT Pre-Booking (Days) | P1: TAT Booking (Days) | Q1: TAT Delivery (Days) | R1: Customer Rating | S1: NPS
A2: L1000 | B2: Bangalore MBC | C2: Warm | D2: 45951 | E2: 45955 | F2: 45959 | G2: 45964 | H2: =IF(G2<>"","Delivered",IF(F2<>"","Booked",IF(E2<>"","Pre-Booked",IF(D2<>"","Lead","")))) -> Delivered | I2: =IF(E2>D2,E2-D2,0) -> 4 | J2: =IF(F2>E2,F2-E2,0) -> 4 | K2: =IF(G2>F2,G2-F2,0) -> 5 | L2: No | N2: 45989 | O2: 4 | P2: 4 | Q2: 5 | R2: 2 | S2: =IF(R2>=9,"Promoter",IF(R2>=7,"Passive","Detractor")) -> Detractor
A3: L1001 | B3: Delhi MBC | C3: Warm | D3: 45941 | E3: 45944 | F3: 45949 | G3: 45956 | H3: =IF(G3<>"","Delivered",IF(F3<>"","Booked",IF(E3<>"","Pre-Booked",IF(D3<>"","Lead","")))) -> Delivered | I3: =IF(E3>D3,E3-D3,0) -> 3 | J3: =IF(F3>E3,F3-E3,0) -> 5 | K3: =IF(G3>F3,G3-F3,0) -> 7 | L3: No | N3: 45983 | O3: 3 | P3: 5 | Q3: 7 | R3: 8 | S3: =IF(R3>=9,"Promoter",IF(R3>=7,"Passive","Detractor")) -> Passive
A4: L1002 | B4: Mumbai MBC | C4: Cold | D4: 45931 | H4: =IF(G4<>"","Delivered",IF(F4<>"","Booked",IF(E4<>"","Pre-Booked",IF(D4<>"","Cancelled","")))) -> Cancelled | I4: =IF(E4>D4,E4-D4,0) -> 0 | J4: =IF(F4>E4,F4-E4,0) -> 0 | K4: =IF(G4>F4,G4-F4,0) -> 0 | L4: Yes | M4: Other | S4: =IF(R4>=9,"Promoter",IF(R4>=7,"Passive","Detractor")) -> Detractor
A5: L1003 | B5: Bangalore MBC | C5: Cold | D5: 45958 | H5: =IF(G5<>"","Delivered",IF(F5<>"","Booked",IF(E5<>"","Pre-Booked",IF(D5<>"","Cancelled","")))) -> Cancelled | I5: =IF(E5>D5,E5-D5,0) -> 0 | J5: =IF(F5>E5,F5-E5,0) -> 0 | K5: =IF(G5>F5,G5-F5,0) -> 0 | L5: Yes | M5: Model Unavailable | S5: =IF(R5>=9,"Promoter",IF(R5>=7,"Passive","Detractor")) -> Detractor
A6: L1004 | B6: Delhi MBC | C6: Warm | D6: 45944 | E6: 45948 | F6: 45951 | G6: 45954 | H6: =IF(G6<>"","Delivered",IF(F6<>"","Booked",IF(E6<>"","Pre-Booked",IF(D6<>"","Cancelled","")))) -> Delivered | I6: =IF(E6>D6,E6-D6,0) -> 4 | J6: =IF(F6>E6,F6-E6,0) -> 3 | K6: =IF(G6>F6,G6-F6,0) -> 3 | L6: No | N6: 45973 | O6: 4 | P6: 3 | Q6: 3 | R6: 8 | S6: =IF(R6>=9,"Promoter",IF(R6>=7,"Passive","Detractor")) -> Passive
A7: L1005 | B7: Delhi MBC | C7: Warm | D7: 45957 | E7: 45961 | F7: 45965 | G7: 45968 | H7: =IF(G7<>"","Delivered",IF(F7<>"","Booked",IF(E7<>"","Pre-Booked",IF(D7<>"","Cancelled","")))) -> Delivered | I7: =IF(E7>D7,E7-D7,0) -> 4 | J7: =IF(F7>E7,F7-E7,0) -> 4 | K7: =IF(G7>F7,G7-F7,0) -> 3 | L7: No | N7: 45983 | O7: 4 | P7: 4 | Q7: 3 | R7: 9 | S7: =IF(R7>=9,"Promoter",IF(R7>=7,"Passive","Detractor")) -> Promoter
A8: L1006 | B8: Mumbai MBC | C8: Hot | D8: 45946 | E8: 45950 | F8: 45951 | G8: 45958 | H8: =IF(G8<>"","Delivered",IF(F8<>"","Booked",IF(E8<>"","Pre-Booked",IF(D8<>"","Cancelled","")))) -> Delivered | I8: =IF(E8>D8,E8-D8,0) -> 4 | J8: =IF(F8>E8,F8-E8,0) -> 1 | K8: =IF(G8>F8,G8-F8,0) -> 7 | L8: No | N8: 45983 | O8: 4 | P8: 1 | Q8: 7 | R8: 10 | S8: =IF(R8>=9,"Promoter",IF(R8>=7,"Passive","Detractor")) -> Promoter
A9: L1007 | B9: Chennai MBC | C9: Warm | D9: 45934 | E9: 45935 | F9: 45938 | G9: 45945 | H9: =IF(G9<>"","Delivered",IF(F9<>"","Booked",IF(E9<>"","Pre-Booked",IF(D9<>"","Cancelled","")))) -> Delivered | I9: =IF(E9>D9,E9-D9,0) -> 1 | J9: =IF(F9>E9,F9-E9,0) -> 3 | K9: =IF(G9>F9,G9-F9,0) -> 7 | L9: Yes | M9: Changed Mind | O9: 1 | P9: 3 | Q9: 7 | S9: =IF(R9>=9,"Promoter",IF(R9>=7,"Passive","Detractor")) -> Detractor
A10: L1008 | B10: Bangalore MBC | C10: Hot | D10: 45944 | E10: 45947 | F10: 45950 | G10: 45955 | H10: =IF(G10<>"","Delivered",IF(F10<>"","Booked",IF(E10<>"","Pre-Booked",IF(D10<>"","Cancelled","")))) -> Delivered | I10: =IF(E10>D10,E10-D10,0) -> 3 | J10: =IF(F10>E10,F10-E10,0) -> 3 | K10: =IF(G10>F10,G10-F10,0) -> 5 | L10: No | N10: 45966 | O10: 3 | P10: 3 | Q10: 5 | R10: 8 | S10: =IF(R10>=9,"Promoter",IF(R10>=7,"Passive","Detractor")) -> Passive
A11: L1009 | B11: Mumbai MBC | C11: Warm | D11: 45961 | E11: 45965 | F11: 45966 | G11: 45971 | H11: =IF(G11<>"","Delivered",IF(F11<>"","Booked",IF(E11<>"","Pre-Booked",IF(D11<>"","Cancelled","")))) -> Delivered | I11: =IF(E11>D11,E11-D11,0) -> 4 | J11: =IF(F11>E11,F11-E11,0) -> 1 | K11: =IF(G11>F11,G11-F11,0) -> 5 | L11: No | N11: 45983 | O11: 4 | P11: 1 | Q11: 5 | R11: 6 | S11: =IF(R11>=9,"Promoter",IF(R11>=7,"Passive","Detractor")) -> Detractor
A12: L1010 | B12: Bangalore MBC | C12: Cold | D12: 45942 | H12: =IF(G12<>"","Delivered",IF(F12<>"","Booked",IF(E12<>"","Pre-Booked",IF(D12<>"","Cancelled","")))) -> Cancelled | I12: =IF(E12>D12,E12-D12,0) -> 0 | J12: =IF(F12>E12,F12-E12,0) -> 0 | K12: =IF(G12>F12,G12-F12,0) -> 0 | L12: Yes | M12: Other | S12: =IF(R12>=9,"Promoter",IF(R12>=7,"Passive","Detractor")) -> Detractor
A13: L1011 | B13: Delhi MBC | C13: Warm | D13: 45951 | E13: 45954 | F13: 45958 | G13: 45960 | H13: =IF(G13<>"","Delivered",IF(F13<>"","Booked",IF(E13<>"","Pre-Booked",IF(D13<>"","Cancelled","")))) -> Delivered | I13: =IF(E13>D13,E13-D13,0) -> 3 | J13: =IF(F13>E13,F13-E13,0) -> 4 | K13: =IF(G13>F13,G13-F13,0) -> 2 | L13: No | N13: 45971 | O13: 3 | P13: 4 | Q13: 2 | R13: 0 | S13: =IF(R13>=9,"Promoter",IF(R13>=7,"Passive","Detractor")) -> Detractor
A14: L1012 | B14: Delhi MBC | C14: Warm | D14: 45959 | E14: 45962 | F14: 45967 | G14: 45974 | H14: =IF(G14<>"","Delivered",IF(F14<>"","Booked",IF(E14<>"","Pre-Booked",IF(D14<>"","Cancelled","")))) -> Delivered | I14: =IF(E14>D14,E14-D14,0) -> 3 | J14: =IF(F14>E14,F14-E14,0) -> 5 | K14: =IF(G14>F14,G14-F14,0) -> 7 | L14: No | N14: 45991 | O14: 3 | P14: 5 | Q14: 7 | R14: 10 | S14: =IF(R14>=9,"Promoter",IF(R14>=7,"Passive","Detractor")) -> Promoter
A15: L1013 | B15: Chennai MBC | C15: Warm | D15: 45957 | E15: 45960 | F15: 45963 | G15: 45969 | H15: =IF(G15<>"","Delivered",IF(F15<>"","Booked",IF(E15<>"","Pre-Booked",IF(D15<>"","Cancelled","")))) -> Delivered | I15: =IF(E15>D15,E15-D15,0) -> 3 | J15: =IF(F15>E15,F15-E15,0) -> 3 | K15: =IF(G15>F15,G15-F15,0) -> 6 | L15: No | N15: 45998 | O15: 3 | P15: 3 | Q15: 6 | R15: 2 | S15: =IF(R15>=9,"Promoter",IF(R15>=7,"Passive","Detractor")) -> Detractor
A16: L1014 | B16: Delhi MBC | C16: Hot | D16: 45945 | E16: 45947 | F16: 45948 | G16: 45951 | H16: =IF(G16<>"","Delivered",IF(F16<>"","Booked",IF(E16<>"","Pre-Booked",IF(D16<>"","Cancelled","")))) -> Delivered | I16: =IF(E16>D16,E16-D16,0) -> 2 | J16: =IF(F16>E16,F16-E16,0) -> 1 | K16: =IF(G16>F16,G16-F16,0) -> 3 | L16: Yes | M16: Changed Mind | O16: 2 | P16: 1 | Q16: 3 | S16: =IF(R16>=9,"Promoter",IF(R16>=7,"Passive","Detractor")) -> Detractor
A17: L1015 | B17: Delhi MBC | C17: Warm | D17: 45953 | E17: 45957 | F17: 45962 | G17: 45967 | H17: =IF(G17<>"","Delivered",IF(F17<>"","Booked",IF(E17<>"","Pre-Booked",IF(D17<>"","Cancelled","")))) -> Delivered | I17: =IF(E17>D17,E17-D17,0) -> 4 | J17: =IF(F17>E17,F17-E17,0) -> 5 | K17: =IF(G17>F17,G17-F17,0) -> 5 | L17: No | N17: 45984 | O17: 4 | P17: 5 | Q17: 5 | R17: 8 | S17: =IF(R17>=9,"Promoter",IF(R17>=7,"Passive","Detractor")) -> Passive
A18: L1016 | B18: Mumbai MBC | C18: Hot | D18: 45935 | E18: 45936 | F18: 45940 | G18: 45946 | H18: =IF(G18<>"","Delivered",IF(F18<>"","Booked",IF(E18<>"","Pre-Booked",IF(D18<>"","Cancelled","")))) -> Delivered | I18: =IF(E18>D18,E18-D18,0) -> 1 | J18: =IF(F18>E18,F18-E18,0) -> 4 | K18: =IF(G18>F18,G18-F18,0) -> 6 | L18: No | N18: 45956 | O18: 1 | P18: 4 | Q18: 6 | R18: 2 | S18: =IF(R18>=9,"Promoter",IF(R18>=7,"Passive","Detractor")) -> Detractor
A19: L1017 | B19: Bangalore MBC | C19: Hot | D19: 45944 | E19: 45945 | F19: 45948 | G19: 45953 | H19: =IF(G19<>"","Delivered",IF(F19<>"","Booked",IF(E19<>"","Pre-Booked",IF(D19<>"","Cancelled","")))) -> Delivered | I19: =IF(E19>D19,E19-D19,0) -> 1 | J19: =IF(F19>E19,F19-E19,0) -> 3 | K19: =IF(G19>F19,G19-F19,0) -> 5 | L19: No | N19: 45979 | O19: 1 | P19: 3 | Q19: 5 | R19: 0 | S19: =IF(R19>=9,"Promoter",IF(R19>=7,"Passive","Detractor")) -> Detractor
A20: L1018 | B20: Bangalore MBC | C20: Warm | D20: 45936 | E20: 45937 | F20: 45942 | G20: 45947 | H20: =IF(G20<>"","Delivered",IF(F20<>"","Booked",IF(E20<>"","Pre-Booked",IF(D20<>"","Cancelled","")))) -> Delivered | I20: =IF(E20>D20,E20-D20,0) -> 1 | J20: =IF(F20>E20,F20-E20,0) -> 5 | K20: =IF(G20>F20,G20-F20,0) -> 5 | L20: No | N20: 45972 | O20: 1 | P20: 5 | Q20: 5 | R20: 5 | S20: =IF(R20>=9,"Promoter",IF(R20>=7,"Passive","Detractor")) -> Detractor
A21: L1019 | B21: Mumbai MBC | C21: Warm | D21: 45954 | E21: 45955 | F21: 45960 | G21: 45962 | H21: =IF(G21<>"","Delivered",IF(F21<>"","Booked",IF(E21<>"","Pre-Booked",IF(D21<>"","Cancelled","")))) -> Delivered | I21: =IF(E21>D21,E21-D21,0) -> 1 | J21: =IF(F21>E21,F21-E21,0) -> 5 | K21: =IF(G21>F21,G21-F21,0) -> 2 | L21: No | N21: 45972 | O21: 1 | P21: 5 | Q21: 2 | R21: 4 | S21: =IF(R21>=9,"Promoter",IF(R21>=7,"Passive","Detractor")) -> Detractor
A22: L1020 | B22: Chennai MBC | C22: Warm | D22: 45947 | E22: 45951 | F22: 45953 | G22: 45960 | H22: =IF(G22<>"","Delivered",IF(F22<>"","Booked",IF(E22<>"","Pre-Booked",IF(D22<>"","Cancelled","")))) -> Delivered | I22: =IF(E22>D22,E22-D22,0) -> 4 | J22: =IF(F22>E22,F22-E22,0) -> 2 | K22: =IF(G22>F22,G22-F22,0) -> 7 | L22: No | N22: 45980 | O22: 4 | P22: 2 | Q22: 7 | R22: 6 | S22: =IF(R22>=9,"Promoter",IF(R22>=7,"Passive","Detractor")) -> Detractor
A23: L1021 | B23: Bangalore MBC | C23: Hot | D23: 45961 | E23: 45962 | F23: 45963 | G23: 45966 | H23: =IF(G23<>"","Delivered",IF(F23<>"","Booked",IF(E23<>"","Pre-Booked",IF(D23<>"","Cancelled","")))) -> Delivered | I23: =IF(E23>D23,E23-D23,0) -> 1 | J23: =IF(F23>E23,F23-E23,0) -> 1 | K23: =IF(G23>F23,G23-F23,0) -> 3 | L23: No | N23: 45995 | O23: 1 | P23: 1 | Q23: 3 | R23: 3 | S23: =IF(R23>=9,"Promoter",IF(R23>=7,"Passive","Detractor")) -> Detractor
A24: L1022 | B24: Delhi MBC | C24: Warm | D24: 45951 | E24: 45954 | F24: 45959 | G24: 45962 | H24: =IF(G24<>"","Delivered",IF(F24<>"","Booked",IF(E24<>"","Pre-Booked",IF(D24<>"","Cancelled","")))) -> Delivered | I24: =IF(E24>D24,E24-D24,0) -> 3 | J24: =IF(F24>E24,F24-E24,0) -> 5 | K24: =IF(G24>F24,G24-F24,0) -> 3 | L24: No | N24: 45978 | O24: 3 | P24: 5 | Q24: 3 | R24: 8 | S24: =IF(R24>=9,"Promoter",IF(R24>=7,"Passive","Detractor")) -> Passive
A25: L1023 | B25: Bangalore MBC | C25: Warm | D25: 45939 | E25: 45941 | F25: 45945 | G25: 45949 | H25: =IF(G25<>"","Delivered",IF(F25<>"","Booked",IF(E25<>"","Pre-Booked",IF(D25<>"","Cancelled","")))) -> Delivered | I25: =IF(E25>D25,E25-D25,0) -> 2 | J25: =IF(F25>E25,F25-E25,0) -> 4 | K25: =IF(G25>F25,G25-F25,0) -> 4 | L25: No | N25: 45963 | O25: 2 | P25: 4 | Q25: 4 | R25: 3 | S25: =IF(R25>=9,"Promoter",IF(R25>=7,"Passive","Detractor")) -> Detractor
A26: L1024 | B26: Delhi MBC | C26: Warm | D26: 45950 | E26: 45955 | F26: 45957 | G26: 45964 | H26: =IF(G26<>"","Delivered",IF(F26<>"","Booked",IF(E26<>"","Pre-Booked",IF(D26<>"","Cancelled","")))) -> Delivered | I26: =IF(E26>D26,E26-D26,0) -> 5 | J26: =IF(F26>E26,F26-E26,0) -> 2 | K26: =IF(G26>F26,G26-F26,0) -> 7 | L26: No | N26: 45984 | O26: 5 | P26: 2 | Q26: 7 | R26: 1 | S26: =IF(R26>=9,"Promoter",IF(R26>=7,"Passive","Detractor")) -> Detractor
A27: L1025 | B27: Chennai MBC | C27: Warm | D27: 45956 | E27: 45957 | F27: 45962 | G27: 45964 | H27: =IF(G27<>"","Delivered",IF(F27<>"","Booked",IF(E27<>"","Pre-Booked",IF(D27<>"","Cancelled","")))) -> Delivered | I27: =IF(E27>D27,E27-D27,0) -> 1 | J27: =IF(F27>E27,F27-E27,0) -> 5 | K27: =IF(G27>F27,G27-F27,0) -> 2 | L27: No | N27: 45979 | O27: 1 | P27: 5 | Q27: 2 | R27: 4 | S27: =IF(R27>=9,"Promoter",IF(R27>=7,"Passive","Detractor")) -> Detractor
A28: L1026 | B28: Mumbai MBC | C28: Warm | D28: 45960 | E28: 45965 | F28: 45970 | G28: 45976 | H28: =IF(G28<>"","Delivered",IF(F28<>"","Booked",IF(E28<>"","Pre-Booked",IF(D28<>"","Cancelled","")))) -> Delivered | I28: =IF(E28>D28,E28-D28,0) -> 5 | J28: =IF(F28>E28,F28-E28,0) -> 5 | K28: =IF(G28>F28,G28-F28,0) -> 6 | L28: No | N28: 45996 | O28: 5 | P28: 5 | Q28: 6 | R28: 1 | S28: =IF(R28>=9,"Promoter",IF(R28>=7,"Passive","Detractor")) -> Detractor
... A30: L1028 | B30: Mumbai MBC | C30: Warm | D30: 45955 | E30: 45960 | F30: 45962 | G30: 45968 | H30: =IF(G30<>"","Delivered",IF(F30<>"","Booked",IF(E30<>"","Pre-Booked",IF(D30<>"","Cancelled","")))) -> Delivered | I30: =IF(E30>D30,E30-D30,0) -> 5 | J30: =IF(F30>E30,F30-E30,0) -> 2 | K30: =IF(G30>F30,G30-F30,0) -> 6 | L30: No | N30: 45978 | O30: 5 | P30: 2 | Q30: 6 | R30: 3 | S30: =IF(R30>=9,"Promoter",IF(R30>=7,"Passive","Detractor")) -> Detractor
A31: L1029 | B31: Bangalore MBC | C31: Cold | D31: 45946 | H31: =IF(G31<>"","Delivered",IF(F31<>"","Booked",IF(E31<>"","Pre-Booked",IF(D31<>"","Cancelled","")))) -> Cancelled | I31: =IF(E31>D31,E31-D31,0) -> 0 | J31: =IF(F31>E31,F31-E31,0) -> 0 | K31: =IF(G31>F31,G31-F31,0) -> 0 | L31: Yes | M31: Changed Mind | S31: =IF(R31>=9,"Promoter",IF(R31>=7,"Passive","Detractor")) -> Detractor
A32: L1030 | B32: Delhi MBC | C32: Warm | D32: 45945 | E32: 45948 | F32: 45950 | G32: 45953 | H32: =IF(G32<>"","Delivered",IF(F32<>"","Booked",IF(E32<>"","Pre-Booked",IF(D32<>"","Cancelled","")))) -> Delivered | I32: =IF(E32>D32,E32-D32,0) -> 3 | J32: =IF(F32>E32,F32-E32,0) -> 2 | K32: =IF(G32>F32,G32-F32,0) -> 3 | L32: No | N32: 45967 | O32: 3 | P32: 2 | Q32: 3 | R32: 3 | S32: =IF(R32>=9,"Promoter",IF(R32>=7,"Passive","Detractor")) -> Detractor
A33: L1031 | B33: Mumbai MBC | C33: Warm | D33: 45944 | E33: 45945 | F33: 45946 | G33: 45950 | H33: =IF(G33<>"","Delivered",IF(F33<>"","Booked",IF(E33<>"","Pre-Booked",IF(D33<>"","Cancelled","")))) -> Delivered | I33: =IF(E33>D33,E33-D33,0) -> 1 | J33: =IF(F33>E33,F33-E33,0) -> 1 | K33: =IF(G33>F33,G33-F33,0) -> 4 | L33: No | N33: 45978 | O33: 1 | P33: 1 | Q33: 4 | R33: 5 | S33: =IF(R33>=9,"Promoter",IF(R33>=7,"Passive","Detractor")) -> Detractor
A34: L1032 | B34: Bangalore MBC | C34: Warm | D34: 45957 | E34: 45961 | F34: 45966 | G34: 45970 | H34: =IF(G34<>"","Delivered",IF(F34<>"","Booked",IF(E34<>"","Pre-Booked",IF(D34<>"","Cancelled","")))) -> Delivered | I34: =IF(E34>D34,E34-D34,0) -> 4 | J34: =IF(F34>E34,F34-E34,0) -> 5 | K34: =IF(G34>F34,G34-F34,0) -> 4 | L34: No | N34: 45984 | O34: 4 | P34: 5 | Q34: 4 | R34: 3 | S34: =IF(R34>=9,"Promoter",IF(R34>=7,"Passive","Detractor")) -> Detractor
A35: L1033 | B35: Delhi MBC | C35: Warm | D35: 45954 | E35: 45957 | F35: 45958 | G35: 45961 | H35: =IF(G35<>"","Delivered",IF(F35<>"","Booked",IF(E35<>"","Pre-Booked",IF(D35<>"","Cancelled","")))) -> Delivered | I35: =IF(E35>D35,E35-D35,0) -> 3 | J35: =IF(F35>E35,F35-E35,0) -> 1 | K35: =IF(G35>F35,G35-F35,0) -> 3 | L35: No | N35: 45974 | O35: 3 | P35: 1 | Q35: 3 | R35: 3 | S35: =IF(R35>=9,"Promoter",IF(R35>=7,"Passive","Detractor")) -> Detractor
A36: L1034 | B36: Mumbai MBC | C36: Cold | D36: 45949 | H36: =IF(G36<>"","Delivered",IF(F36<>"","Booked",IF(E36<>"","Pre-Booked",IF(D36<>"","Cancelled","")))) -> Cancelled | I36: =IF(E36>D36,E36-D36,0) -> 0 | J36: =IF(F36>E36,F36-E36,0) -> 0 | K36: =IF(G36>F36,G36-F36,0) -> 0 | L36: Yes | M36: Model Unavailable | S36: =IF(R36>=9,"Promoter",IF(R36>=7,"Passive","Detractor")) -> Detractor
A37: L1035 | B37: Mumbai MBC | C37: Warm | D37: 45939 | E37: 45943 | F37: 45945 | G37: 45950 | H37: =IF(G37<>"","Delivered",IF(F37<>"","Booked",IF(E37<>"","Pre-Booked",IF(D37<>"","Cancelled","")))) -> Delivered | I37: =IF(E37>D37,E37-D37,0) -> 4 | J37: =IF(F37>E37,F37-E37,0) -> 2 | K37: =IF(G37>F37,G37-F37,0) -> 5 | L37: No | N37: 45976 | O37: 4 | P37: 2 | Q37: 5 | R37: 9 | S37: =IF(R37>=9,"Promoter",IF(R37>=7,"Passive","Detractor")) -> Promoter
A38: L1036 | B38: Bangalore MBC | C38: Warm | D38: 45941 | E38: 45942 | F38: 45943 | G38: 45945 | H38: =IF(G38<>"","Delivered",IF(F38<>"","Booked",IF(E38<>"","Pre-Booked",IF(D38<>"","Cancelled","")))) -> Delivered | I38: =IF(E38>D38,E38-D38,0) -> 1 | J38: =IF(F38>E38,F38-E38,0) -> 1 | K38: =IF(G38>F38,G38-F38,0) -> 2 | L38: Yes | M38: Financing Issue | O38: 1 | P38: 1 | Q38: 2 | S38: =IF(R38>=9,"Promoter",IF(R38>=7,"Passive","Detractor")) -> Detractor
A39: L1037 | B39: Bangalore MBC | C39: Warm | D39: 45958 | E39: 45961 | F39: 45965 | G39: 45969 | H39: =IF(G39<>"","Delivered",IF(F39<>"","Booked",IF(E39<>"","Pre-Booked",IF(D39<>"","Cancelled","")))) -> Delivered | I39: =IF(E39>D39,E39-D39,0) -> 3 | J39: =IF(F39>E39,F39-E39,0) -> 4 | K39: =IF(G39>F39,G39-F39,0) -> 4 | L39: No | N39: 45990 | O39: 3 | P39: 4 | Q39: 4 | R39: 2 | S39: =IF(R39>=9,"Promoter",IF(R39>=7,"Passive","Detractor")) -> Detractor
A40: L1038 | B40: Bangalore MBC | C40: Warm | D40: 45938 | E40: 45943 | F40: 45946 | G40: 45953 | H40: =IF(G40<>"","Delivered",IF(F40<>"","Booked",IF(E40<>"","Pre-Booked",IF(D40<>"","Cancelled","")))) -> Delivered | I40: =IF(E40>D40,E40-D40,0) -> 5 | J40: =IF(F40>E40,F40-E40,0) -> 3 | K40: =IF(G40>F40,G40-F40,0) -> 7 | L40: No | N40: 45965 | O40: 5 | P40: 3 | Q40: 7 | R40: 9 | S40: =IF(R40>=9,"Promoter",IF(R40>=7,"Passive","Detractor")) -> Promoter
A41: L1039 | B41: Delhi MBC | C41: Warm | D41: 45957 | E41: 45960 | F41: 45964 | G41: 45969 | H41: =IF(G41<>"","Delivered",IF(F41<>"","Booked",IF(E41<>"","Pre-Booked",IF(D41<>"","Cancelled","")))) -> Delivered | I41: =IF(E41>D41,E41-D41,0) -> 3 | J41: =IF(F41>E41,F41-E41,0) -> 4 | K41: =IF(G41>F41,G41-F41,0) -> 5 | L41: Yes | M41: Other | O41: 3 | P41: 4 | Q41: 5 | S41: =IF(R41>=9,"Promoter",IF(R41>=7,"Passive","Detractor")) -> Detractor
...

Sheet Cancellation Patterns
A2: Cancellation patterns by store and reason
A3: Count of Lead ID | B3: Cancellation Reason
A4: Store Name | B4: Changed Mind | C4: Financing Issue | D4: Model Unavailable | E4: Other | F4: Price | G4: Grand Total
A5: Bangalore MBC | B5: 13 | C5: 14 | D5: 13 | E5: 22 | F5: 10 | G5: 72
A6: Chennai MBC | B6: 15 | C6: 10 | D6: 8 | E6: 8 | F6: 18 | G6: 59
A7: Delhi MBC | B7: 14 | C7: 21 | D7: 13 | E7: 13 | F7: 16 | G7: 77
A8: Mumbai MBC | B8: 9 | C8: 14 | D8: 9 | E8: 14 | F8: 17 | G8: 63
A9: Grand Total | B9: 51 | C9: 59 | D9: 43 | E9: 57 | F9: 61 | G9: 271

Sheet NPS Calculation
A2: NPS Calculation
A3: Count of Lead ID | B3: NPS | H3: Store | I3: Promoters | J3: Detractors | K3: Total | L3: NPS (%)
A4: Store Name | B4: Detractor | C4: Passive | D4: Promoter | E4: Grand Total | H4: =A5 -> Bangalore MBC | I4: =D5 -> 23 | J4: =B5 -> 206 | K4: =E5 -> 263 | L4: =((D5-B5)/E5)*100 -> -69.581749
A5: Bangalore MBC | B5: 206 | C5: 34 | D5: 23 | E5: 263 | H5: =A6 -> Chennai MBC | I5: =D6 -> 28 | J5: =B6 -> 158 | K5: =E6 -> 212 | L5: =((D6-B6)/E6)*100 -> -61.320755
A6: Chennai MBC | B6: 158 | C6: 26 | D6: 28 | E6: 212 | H6: =A7 -> Delhi MBC | I6: =D7 -> 30 | J6: =B7 -> 200 | K6: =E7 -> 263 | L6: =((D7-B7)/E7)*100 -> -64.638783
A7: Delhi MBC | B7: 200 | C7: 33 | D7: 30 | E7: 263 | H7: =A8 -> Mumbai MBC | I7: =D8 -> 23 | J7: =B8 -> 201 | K7: =E8 -> 262 | L7: =((D8-B8)/E8)*100 -> -67.938931
A8: Mumbai MBC | B8: 201 | C8: 38 | D8: 23 | E8: 262 | H8: =A9 -> Grand Total | I8: =D9 -> 104 | J8: =B9 -> 765 | K8: =E9 -> 1000 | L8: =((D9-B9)/E9)*100 -> -66.1
A9: Grand Total | B9: 765 | C9: 131 | D9: 104 | E9: 1000
A12: Category | B12: Count of Responses | D12: %
A13: Detractors | B13: 765 | D13: =B13/$B$16 -> 0.765
A14: Passives | B14: =COUNTIFS('Main data'!R:R,">=7",'Main data'!R:R,"<=8") -> 131 | D14: =B14/$B$16 -> 0.131
A15: Promoters | B15: =COUNTIFS('Main data'!R:R,">=9") -> 104 | D15: =B15/$B$16 -> 0.104
A16: Total | B16: =SUM(B13,B14,B15) -> 1000 | D16: =B16/$B$16 -> 1

Sheet Sheet2
A3: Count of Lead ID | B3: Store Name
A4: Customer Rating | B4: Bangalore MBC | C4: Chennai MBC | D4: Delhi MBC | E4: Mumbai MBC | F4: Grand Total
A5: 0 | B5: 9 | C5: 9 | D5: 10 | E5: 8 | F5: 36
A6: 1 | B6: 20 | C6: 18 | D6: 21 | E6: 17 | F6: 76
A7: 2 | B7: 26 | C7: 11 | D7: 21 | E7: 25 | F7: 83
A8: 3 | B8: 25 | C8: 16 | D8: 16 | E8: 20 | F8: 77
A9: 4 | B9: 17 | C9: 16 | D9: 23 | E9: 24 | F9: 80
A10: 5 | B10: 18 | C10: 13 | D10: 10 | E10: 21 | F10: 62
A11: 6 | B11: 19 | C11: 16 | D11: 22 | E11: 23 | F11: 80
A12: 7 | B12: 14 | C12: 16 | D12: 19 | E12: 20 | F12: 69
A13: 8 | B13: 20 | C13: 10 | D13: 14 | E13: 18 | F13: 62
A14: 9 | B14: 15 | C14: 18 | D14: 19 | E14: 14 | F14: 66
A15: 10 | B15: 8 | C15: 10 | D15: 11 | E15: 9 | F15: 38
A16: Grand Total | B16: 191 | C16: 153 | D16: 186 | E16: 199 | F16: 729

Sheet Dashboard
